Workbook

Sheet Dashboard
A1: Tổng hợp đăng ký bán hàng nội bộ
A2: Số liệu tự tính từ sheet Registrations và Slots. Ô nền vàng ở sheet Config là ô cần điền.
A4: 1. Theo kho
A5: Kho | B5: Tổng slot | C5: Đã đăng ký | D5: Còn trống | E5: Tỷ lệ đã đăng ký
A6: AYA | B6: =COUNTIF(Slots!$A$2:$A$91,$A6) -> 44 | C6: =COUNTIFS(Slots!$A$2:$A$91,$A6,Slots!$E$2:$E$91,"<>Còn trống") -> 0 | D6: =B6-C6 -> 44 | E6: =IF(B6=0,0,C6/B6) -> 0
A7: AYB | B7: =COUNTIF(Slots!$A$2:$A$91,$A7) -> 1 | C7: =COUNTIFS(Slots!$A$2:$A$91,$A7,Slots!$E$2:$E$91,"<>Còn trống") -> 0 | D7: =B7-C7 -> 1 | E7: =IF(B7=0,0,C7/B7) -> 0
A8: AYC | B8: =COUNTIF(Slots!$A$2:$A$91,$A8) -> 45 | C8: =COUNTIFS(Slots!$A$2:$A$91,$A8,Slots!$E$2:$E$91,"<>Còn trống") -> 0 | D8: =B8-C8 -> 45 | E8: =IF(B8=0,0,C8/B8) -> 0
A9: Tổng | B9: =SUM(B6:B8) -> 90 | C9: =SUM(C6:C8) -> 0 | D9: =SUM(D6:D8) -> 90 | E9: =IF(B9=0,0,C9/B9) -> 0
A11: 2. Theo trạng thái đơn
A12: Trạng thái | B12: Số đơn
A13: Chờ nộp tiền | B13: =COUNTIF(Registrations!$L$2:$L1000,$A13) -> 0
A14: Đã khai nộp - chờ đối soát | B14: =COUNTIF(Registrations!$L$2:$L1000,$A14) -> 0
A15: Đã xác nhận | B15: =COUNTIF(Registrations!$L$2:$L1000,$A15) -> 0
A16: Từ chối | B16: =COUNTIF(Registrations!$L$2:$L1000,$A16) -> 0
A17: Hủy | B17: =COUNTIF(Registrations!$L$2:$L1000,$A17) -> 0
A18: Chưa có trạng thái | B18: =COUNTIFS(Registrations!$D$2:$D1000,"<>",Registrations!$L$2:$L1000,"") -> 0
A19: Tổng số đơn | B19: =SUM(B13:B18) -> 0
A21: 3. Kiểm soát (Jeong-Do)
A22: Chỉ tiêu | B22: Kết quả | C22: Cần làm khi khác 0
A23: Tổng lượt đăng ký | B23: =COUNTA(Registrations!$D$2:$D1000) -> 0
A24: Số mã NV khác nhau | B24: =IFERROR(__xludf.DUMMYFUNCTION("COUNTUNIQUE(Registrations!$D$2:$D1000)"),0.0) -> 0
A25: Lượt đăng ký vượt hạn mức 1 SP/NV | B25: =B23-B24 -> 0 | C25: Lọc cột Mã NV (tô đỏ) để xử lý đơn thừa
A26: Slot bị đăng ký trùng | B26: =COUNTIF(Slots!$E$2:$E$91,"Trùng đăng ký") -> 0 | C26: Xét theo Timestamp, giữ người đến trước
A27: Đăng ký sai kho so với slot | B27: =COUNTIF(Slots!$I$2:$I$91,"Sai kho") -> 0 | C27: Liên hệ NV xác nhận lại kho
A28: Slot không có trong danh sách | B28: =SUMPRODUCT((Registrations!$H$2:$H1000<>"")*(COUNTIF(Slots!$C$2:$C$91,Registrations!$H$2:$H1000)=0)) -> 0 | C28: Kiểm tra mã slot NV nhập
A29: Chưa xác nhận cam kết Jeong-Do | B29: =COUNTIFS(Registrations!$D$2:$D1000,"<>",Registrations!$K$2:$K1000,"<>Đồng ý") -> 0 | C29: Yêu cầu NV xác nhận trước khi giao hàng
A30: Nộp hộ (người nộp khác người đăng ký) | B30: =SUMPRODUCT((Registrations!$N$2:$N1000<>"")*(Registrations!$N$2:$N1000<>Registrations!$D$2:$D1000)) -> 0 | C30: Đối chiếu sao kê theo tên người nộp

Sheet PM xử lý
A1: PM xử lý: danh sách đơn cần đối soát
A2: ="Chờ đối soát: "&COUNTIF(Registrations!$L$2:$L1000,"Đã khai nộp - chờ đối soát")&" | Chờ nộp tiền: "&COUNTIF(Registrations!$L$2:$L1000,"Chờ nộp tiền")&" | Đã xác nhận: "&COUNTIF(Registrations!$L$2:$L1000,"Đã xác nhận")&" | Nộp hộ: "&SUMPRODUCT((Registrations!$M$2:$M1000<>"")*(UPPER(Registrations!$N$2:$N1000)<>UPPER(Registrations!$D$2:$D1000))) -> Chờ đối soát: 0 | Chờ nộp tiền: 0 | Đã xác nhận: 0 | Nộp hộ: 0
A3: Sheet này tự cập nhật và chỉ để xem. Đơn chờ đối soát xếp trên cùng, rồi theo thứ tự thời gian. Muốn đổi trạng thái: bấm "Sửa dòng" ở cột A để nhảy tới đúng dòng trong Registrations, chọn trạng thái ở cột L.
A5: Sửa | B5: Trạng thái | C5: Thời gian đăng ký | D5: Mã NV | E5: Họ tên | F5: Bộ phận | G5: Kho | H5: Slot | I5: Model | J5: NV nộp tiền | K5: Mã NV nộp | L5: Nộp hộ? | M5: Số tiền | N5: Ngân hàng & Mã GD | O5: Giờ nộp | P5: Biên lai | Q5: Ghi chú
A6: =IFERROR(__xludf.DUMMYFUNCTION("IFERROR(ARRAYFORMULA(SORT(FILTER({HYPERLINK(""#gid=1&range=L""&ROW(Registrations!$A$2:$A1000),""Sửa dòng ""&ROW(Registrations!$A$2:$A1000)),Registrations!$L$2:$L1000,Registrations!$A$2:$A1000,Registrations!$D$2:$D1000,Registrations!$E$2:$E1000,Registratio"&"ns!$C$2:$C1000,Registrations!$F$2:$F1000,Registrations!$H$2:$H1000,Registrations!$G$2:$G1000,Registrations!$M$2:$M1000,Registrations!$N$2:$N1000,IF(Registrations!$M$2:$M1000="""","""",IF(UPPER(Registrations!$N$2:$N1000)=UPPER(Registrations!$D$2:$D1000),"""&""",""Nộp hộ"")),Registrations!$O$2:$O1000,Registrations!$P$2:$P1000,Registrations!$Q$2:$Q1000,IF(Registrations!$R$2:$R1000="""","""",HYPERLINK(Registrations!$R$2:$R1000,""Xem biên lai"")),Registrations!$U$2:$U1000},Registrations!$D$2:$D1000<>""""),FILTER("&"IFERROR(MATCH(Registrations!$L$2:$L1000,{""Đã khai nộp - chờ đối soát"",""Chờ nộp tiền"",""Đã xác nhận"",""Từ chối"",""Hủy""},0),9),Registrations!$D$2:$D1000<>""""),TRUE,FILTER(Registrations!$A$2:$A1000,Registrations!$D$2:$D1000<>""""),TRUE)),""Chưa có đơ"&"n"")"),"Chưa có đơn") -> Chưa có đơn

Sheet Registrations
A1: Timestamp | B1: Mã Đợt | C1: Bộ Phận | D1: Mã NV Đăng Ký | E1: Họ Tên NV Đăng Ký | F1: Kho | G1: Mã Model | H1: Slot ID | I1: Số Điện Thoại | J1: Địa Chỉ Giao Hàng | K1: Cam Kết Jeong-Do | L1: Trạng Thái | M1: Họ Tên NV Nộp Tiền | N1: Mã NV Nộp Tiền | O1: Số Tiền Đã Chuyển Khoản | P1: Ngân Hàng & Mã GD | Q1: Thời Gian Nộp Tiền | R1: Link Biên Lai | S1: PM Xác Nhận Bởi | T1: Ngày PM Xác Nhận | U1: Ghi Chú | V1: User Agent | W1: Mã yêu cầu (hệ thống)

Sheet Slots
A1: WH (Kho) | B1: No | C1: Slot ID | D1: Model | E1: Trạng Thái Slot | F1: Số Lượt Đăng Ký | G1: Mã NV Đăng Ký | H1: Họ Tên NV Đăng Ký | I1: Khớp Kho | J1: Loại (Grade) | K1: Giá bán (VNĐ)
A2: AYC | B2: 1 | C2: #001 | D2: 27LX6TDGA.ATV | E2: =IF(F2=0,"Còn trống",IF(F2=1,"Đã đăng ký","Trùng đăng ký")) -> Còn trống | F2: =COUNTIFS(Registrations!$H$2:$H100,$C2,Registrations!$L$2:$L100,"<>Hủy",Registrations!$L$2:$L100,"<>Từ chối") -> 0 | G2: =IFERROR(__xludf.DUMMYFUNCTION("IFERROR(INDEX(FILTER(Registrations!$D$2:$D100,Registrations!$H$2:$H100=$C2,Registrations!$L$2:$L100<>""Hủy"",Registrations!$L$2:$L100<>""Từ chối""),1),"""")"),"") | H2: =IFERROR(__xludf.DUMMYFUNCTION("IFERROR(INDEX(FILTER(Registrations!$E$2:$E100,Registrations!$H$2:$H100=$C2,Registrations!$L$2:$L100<>""Hủy"",Registrations!$L$2:$L100<>""Từ chối""),1),"""")"),"") | I2: =IFERROR(__xludf.DUMMYFUNCTION("IF(F2=0,"""",IF(IFERROR(INDEX(FILTER(Registrations!$F$2:$F100,Registrations!$H$2:$H100=$C2,Registrations!$L$2:$L100<>""Hủy"",Registrations!$L$2:$L100<>""Từ chối""),1),"""")=$A2,""Khớp"",""Sai kho""))"),"") | J2: A | K2: 5085000
A3: AYC | B3: 2 | C3: #002 | D3: 43UA8450PSA.ATV | E3: =IF(F3=0,"Còn trống",IF(F3=1,"Đã đăng ký","Trùng đăng ký")) -> Còn trống | F3: =COUNTIFS(Registrations!$H$2:$H100,$C3,Registrations!$L$2:$L100,"<>Hủy",Registrations!$L$2:$L100,"<>Từ chối") -> 0 | G3: =IFERROR(__xludf.DUMMYFUNCTION("IFERROR(INDEX(FILTER(Registrations!$D$2:$D100,Registrations!$H$2:$H100=$C3,Registrations!$L$2:$L100<>""Hủy"",Registrations!$L$2:$L100<>""Từ chối""),1),"""")"),"") | H3: =IFERROR(__xludf.DUMMYFUNCTION("IFERROR(INDEX(FILTER(Registrations!$E$2:$E100,Registrations!$H$2:$H100=$C3,Registrations!$L$2:$L100<>""Hủy"",Registrations!$L$2:$L100<>""Từ chối""),1),"""")"),"") | I3: =IFERROR(__xludf.DUMMYFUNCTION("IF(F3=0,"""",IF(IFERROR(INDEX(FILTER(Registrations!$F$2:$F100,Registrations!$H$2:$H100=$C3,Registrations!$L$2:$L100<>""Hủy"",Registrations!$L$2:$L100<>""Từ chối""),1),"""")=$A3,""Khớp"",""Sai kho""))"),"") | J3: B | K3: 2672500
A4: AYC | B4: 3 | C4: #003 | D4: 43UQ7050PSA.ATVQ | E4: =IF(F4=0,"Còn trống",IF(F4=1,"Đã đăng ký","Trùng đăng ký")) -> Còn trống | F4: =COUNTIFS(Registrations!$H$2:$H100,$C4,Registrations!$L$2:$L100,"<>Hủy",Registrations!$L$2:$L100,"<>Từ chối") -> 0 | G4: =IFERROR(__xludf.DUMMYFUNCTION("IFERROR(INDEX(FILTER(Registrations!$D$2:$D100,Registrations!$H$2:$H100=$C4,Registrations!$L$2:$L100<>""Hủy"",Registrations!$L$2:$L100<>""Từ chối""),1),"""")"),"") | H4: =IFERROR(__xludf.DUMMYFUNCTION("IFERROR(INDEX(FILTER(Registrations!$E$2:$E100,Registrations!$H$2:$H100=$C4,Registrations!$L$2:$L100<>""Hủy"",Registrations!$L$2:$L100<>""Từ chối""),1),"""")"),"") | I4: =IFERROR(__xludf.DUMMYFUNCTION("IF(F4=0,"""",IF(IFERROR(INDEX(FILTER(Registrations!$F$2:$F100,Registrations!$H$2:$H100=$C4,Registrations!$L$2:$L100<>""Hủy"",Registrations!$L$2:$L100<>""Từ chối""),1),"""")=$A4,""Khớp"",""Sai kho""))"),"") | J4: B | K4: 2672500
A5: AYC | B5: 4 | C5: #004 | D5: 55QNED86ASA.ATV | E5: =IF(F5=0,"Còn trống",IF(F5=1,"Đã đăng ký","Trùng đăng ký")) -> Còn trống | F5: =COUNTIFS(Registrations!$H$2:$H100,$C5,Registrations!$L$2:$L100,"<>Hủy",Registrations!$L$2:$L100,"<>Từ chối") -> 0 | G5: =IFERROR(__xludf.DUMMYFUNCTION("IFERROR(INDEX(FILTER(Registrations!$D$2:$D100,Registrations!$H$2:$H100=$C5,Registrations!$L$2:$L100<>""Hủy"",Registrations!$L$2:$L100<>""Từ chối""),1),"""")"),"") | H5: =IFERROR(__xludf.DUMMYFUNCTION("IFERROR(INDEX(FILTER(Registrations!$E$2:$E100,Registrations!$H$2:$H100=$C5,Registrations!$L$2:$L100<>""Hủy"",Registrations!$L$2:$L100<>""Từ chối""),1),"""")"),"") | I5: =IFERROR(__xludf.DUMMYFUNCTION("IF(F5=0,"""",IF(IFERROR(INDEX(FILTER(Registrations!$F$2:$F100,Registrations!$H$2:$H100=$C5,Registrations!$L$2:$L100<>""Hủy"",Registrations!$L$2:$L100<>""Từ chối""),1),"""")=$A5,""Khớp"",""Sai kho""))"),"") | J5: B | K5: 5850000
A6: AYC | B6: 5 | C6: #005 | D6: 55QNED86BSA.ATV | E6: =IF(F6=0,"Còn trống",IF(F6=1,"Đã đăng ký","Trùng đăng ký")) -> Còn trống | F6: =COUNTIFS(Registrations!$H$2:$H100,$C6,Registrations!$L$2:$L100,"<>Hủy",Registrations!$L$2:$L100,"<>Từ chối") -> 0 | G6: =IFERROR(__xludf.DUMMYFUNCTION("IFERROR(INDEX(FILTER(Registrations!$D$2:$D100,Registrations!$H$2:$H100=$C6,Registrations!$L$2:$L100<>""Hủy"",Registrations!$L$2:$L100<>""Từ chối""),1),"""")"),"") | H6: =IFERROR(__xludf.DUMMYFUNCTION("IFERROR(INDEX(FILTER(Registrations!$E$2:$E100,Registrations!$H$2:$H100=$C6,Registrations!$L$2:$L100<>""Hủy"",Registrations!$L$2:$L100<>""Từ chối""),1),"""")"),"") | I6: =IFERROR(__xludf.DUMMYFUNCTION("IF(F6=0,"""",IF(IFERROR(INDEX(FILTER(Registrations!$F$2:$F100,Registrations!$H$2:$H100=$C6,Registrations!$L$2:$L100<>""Hủy"",Registrations!$L$2:$L100<>""Từ chối""),1),"""")=$A6,""Khớp"",""Sai kho""))"),"") | J6: B | K6: 5975000
A7: AYC | B7: 6 | C7: #006 | D7: 55UA8450PSA.ATV | E7: =IF(F7=0,"Còn trống",IF(F7=1,"Đã đăng ký","Trùng đăng ký")) -> Còn trống | F7: =COUNTIFS(Registrations!$H$2:$H100,$C7,Registrations!$L$2:$L100,"<>Hủy",Registrations!$L$2:$L100,"<>Từ chối") -> 0 | G7: =IFERROR(__xludf.DUMMYFUNCTION("IFERROR(INDEX(FILTER(Registrations!$D$2:$D100,Registrations!$H$2:$H100=$C7,Registrations!$L$2:$L100<>""Hủy"",Registrations!$L$2:$L100<>""Từ chối""),1),"""")"),"") | H7: =IFERROR(__xludf.DUMMYFUNCTION("IFERROR(INDEX(FILTER(Registrations!$E$2:$E100,Registrations!$H$2:$H100=$C7,Registrations!$L$2:$L100<>""Hủy"",Registrations!$L$2:$L100<>""Từ chối""),1),"""")"),"") | I7: =IFERROR(__xludf.DUMMYFUNCTION("IF(F7=0,"""",IF(IFERROR(INDEX(FILTER(Registrations!$F$2:$F100,Registrations!$H$2:$H100=$C7,Registrations!$L$2:$L100<>""Hủy"",Registrations!$L$2:$L100<>""Từ chối""),1),"""")=$A7,""Khớp"",""Sai kho""))"),"") | J7: B | K7: 3897500
A8: AYC | B8: 7 | C8: #007 | D8: 65QNED80BSA.ATV | E8: =IF(F8=0,"Còn trống",IF(F8=1,"Đã đăng ký","Trùng đăng ký")) -> Còn trống | F8: =COUNTIFS(Registrations!$H$2:$H100,$C8,Registrations!$L$2:$L100,"<>Hủy",Registrations!$L$2:$L100,"<>Từ chối") -> 0 | G8: =IFERROR(__xludf.DUMMYFUNCTION("IFERROR(INDEX(FILTER(Registrations!$D$2:$D100,Registrations!$H$2:$H100=$C8,Registrations!$L$2:$L100<>""Hủy"",Registrations!$L$2:$L100<>""Từ chối""),1),"""")"),"") | H8: =IFERROR(__xludf.DUMMYFUNCTION("IFERROR(INDEX(FILTER(Registrations!$E$2:$E100,Registrations!$H$2:$H100=$C8,Registrations!$L$2:$L100<>""Hủy"",Registrations!$L$2:$L100<>""Từ chối""),1),"""")"),"") | I8: =IFERROR(__xludf.DUMMYFUNCTION("IF(F8=0,"""",IF(IFERROR(INDEX(FILTER(Registrations!$F$2:$F100,Registrations!$H$2:$H100=$C8,Registrations!$L$2:$L100<>""Hủy"",Registrations!$L$2:$L100<>""Từ chối""),1),"""")=$A8,""Khớp"",""Sai kho""))"),"") | J8: B | K8: 6350000
A9: AYC | B9: 8 | C9: #008 | D9: 65QNED86ASA.ATV | E9: =IF(F9=0,"Còn trống",IF(F9=1,"Đã đăng ký","Trùng đăng ký")) -> Còn trống | F9: =COUNTIFS(Registrations!$H$2:$H100,$C9,Registrations!$L$2:$L100,"<>Hủy",Registrations!$L$2:$L100,"<>Từ chối") -> 0 | G9: =IFERROR(__xludf.DUMMYFUNCTION("IFERROR(INDEX(FILTER(Registrations!$D$2:$D100,Registrations!$H$2:$H100=$C9,Registrations!$L$2:$L100<>""Hủy"",Registrations!$L$2:$L100<>""Từ chối""),1),"""")"),"") | H9: =IFERROR(__xludf.DUMMYFUNCTION("IFERROR(INDEX(FILTER(Registrations!$E$2:$E100,Registrations!$H$2:$H100=$C9,Registrations!$L$2:$L100<>""Hủy"",Registrations!$L$2:$L100<>""Từ chối""),1),"""")"),"") | I9: =IFERROR(__xludf.DUMMYFUNCTION("IF(F9=0,"""",IF(IFERROR(INDEX(FILTER(Registrations!$F$2:$F100,Registrations!$H$2:$H100=$C9,Registrations!$L$2:$L100<>""Hủy"",Registrations!$L$2:$L100<>""Từ chối""),1),"""")=$A9,""Khớp"",""Sai kho""))"),"") | J9: B | K9: 7322500
A10: AYC | B10: 9 | C10: #009 | D10: 65QNED86BSA.ATV | E10: =IF(F10=0,"Còn trống",IF(F10=1,"Đã đăng ký","Trùng đăng ký")) -> Còn trống | F10: =COUNTIFS(Registrations!$H$2:$H100,$C10,Registrations!$L$2:$L100,"<>Hủy",Registrations!$L$2:$L100,"<>Từ chối") -> 0 | G10: =IFERROR(__xludf.DUMMYFUNCTION("IFERROR(INDEX(FILTER(Registrations!$D$2:$D100,Registrations!$H$2:$H100=$C10,Registrations!$L$2:$L100<>""Hủy"",Registrations!$L$2:$L100<>""Từ chối""),1),"""")"),"") | H10: =IFERROR(__xludf.DUMMYFUNCTION("IFERROR(INDEX(FILTER(Registrations!$E$2:$E100,Registrations!$H$2:$H100=$C10,Registrations!$L$2:$L100<>""Hủy"",Registrations!$L$2:$L100<>""Từ chối""),1),"""")"),"") | I10: =IFERROR(__xludf.DUMMYFUNCTION("IF(F10=0,"""",IF(IFERROR(INDEX(FILTER(Registrations!$F$2:$F100,Registrations!$H$2:$H100=$C10,Registrations!$L$2:$L100<>""Hủy"",Registrations!$L$2:$L100<>""Từ chối""),1),"""")=$A10,""Khớp"",""Sai kho""))"),"") | J10: B | K10: 7475000
A11: AYC | B11: 10 | C11: #010 | D11: 75QNED82ASA.AGADLHX | E11: =IF(F11=0,"Còn trống",IF(F11=1,"Đã đăng ký","Trùng đăng ký")) -> Còn trống | F11: =COUNTIFS(Registrations!$H$2:$H100,$C11,Registrations!$L$2:$L100,"<>Hủy",Registrations!$L$2:$L100,"<>Từ chối") -> 0 | G11: =IFERROR(__xludf.DUMMYFUNCTION("IFERROR(INDEX(FILTER(Registrations!$D$2:$D100,Registrations!$H$2:$H100=$C11,Registrations!$L$2:$L100<>""Hủy"",Registrations!$L$2:$L100<>""Từ chối""),1),"""")"),"") | H11: =IFERROR(__xludf.DUMMYFUNCTION("IFERROR(INDEX(FILTER(Registrations!$E$2:$E100,Registrations!$H$2:$H100=$C11,Registrations!$L$2:$L100<>""Hủy"",Registrations!$L$2:$L100<>""Từ chối""),1),"""")"),"") | I11: =IFERROR(__xludf.DUMMYFUNCTION("IF(F11=0,"""",IF(IFERROR(INDEX(FILTER(Registrations!$F$2:$F100,Registrations!$H$2:$H100=$C11,Registrations!$L$2:$L100<>""Hủy"",Registrations!$L$2:$L100<>""Từ chối""),1),"""")=$A11,""Khớp"",""Sai kho""))"),"") | J11: B | K11: 9975000
A12: AYC | B12: 11 | C12: #011 | D12: 75QNED86BSA.ATV | E12: =IF(F12=0,"Còn trống",IF(F12=1,"Đã đăng ký","Trùng đăng ký")) -> Còn trống | F12: =COUNTIFS(Registrations!$H$2:$H100,$C12,Registrations!$L$2:$L100,"<>Hủy",Registrations!$L$2:$L100,"<>Từ chối") -> 0 | G12: =IFERROR(__xludf.DUMMYFUNCTION("IFERROR(INDEX(FILTER(Registrations!$D$2:$D100,Registrations!$H$2:$H100=$C12,Registrations!$L$2:$L100<>""Hủy"",Registrations!$L$2:$L100<>""Từ chối""),1),"""")"),"") | H12: =IFERROR(__xludf.DUMMYFUNCTION("IFERROR(INDEX(FILTER(Registrations!$E$2:$E100,Registrations!$H$2:$H100=$C12,Registrations!$L$2:$L100<>""Hủy"",Registrations!$L$2:$L100<>""Từ chối""),1),"""")"),"") | I12: =IFERROR(__xludf.DUMMYFUNCTION("IF(F12=0,"""",IF(IFERROR(INDEX(FILTER(Registrations!$F$2:$F100,Registrations!$H$2:$H100=$C12,Registrations!$L$2:$L100<>""Hủy"",Registrations!$L$2:$L100<>""Từ chối""),1),"""")=$A12,""Khớp"",""Sai kho""))"),"") | J12: B | K12: 10475000
A13: AYC | B13: 12 | C13: #012 | D13: 75QNED9MASA.AGAFLHX | E13: =IF(F13=0,"Còn trống",IF(F13=1,"Đã đăng ký","Trùng đăng ký")) -> Còn trống | F13: =COUNTIFS(Registrations!$H$2:$H100,$C13,Registrations!$L$2:$L100,"<>Hủy",Registrations!$L$2:$L100,"<>Từ chối") -> 0 | G13: =IFERROR(__xludf.DUMMYFUNCTION("IFERROR(INDEX(FILTER(Registrations!$D$2:$D100,Registrations!$H$2:$H100=$C13,Registrations!$L$2:$L100<>""Hủy"",Registrations!$L$2:$L100<>""Từ chối""),1),"""")"),"") | H13: =IFERROR(__xludf.DUMMYFUNCTION("IFERROR(INDEX(FILTER(Registrations!$E$2:$E100,Registrations!$H$2:$H100=$C13,Registrations!$L$2:$L100<>""Hủy"",Registrations!$L$2:$L100<>""Từ chối""),1),"""")"),"") | I13: =IFERROR(__xludf.DUMMYFUNCTION("IF(F13=0,"""",IF(IFERROR(INDEX(FILTER(Registrations!$F$2:$F100,Registrations!$H$2:$H100=$C13,Registrations!$L$2:$L100<>""Hủy"",Registrations!$L$2:$L100<>""Từ chối""),1),"""")=$A13,""Khớp"",""Sai kho""))"),"") | J13: B | K13: 12475000
A14: AYC | B14: 13 | C14: #013 | D14: OLED65G5PSA.ATV | E14: =IF(F14=0,"Còn trống",IF(F14=1,"Đã đăng ký","Trùng đăng ký")) -> Còn trống | F14: =COUNTIFS(Registrations!$H$2:$H100,$C14,Registrations!$L$2:$L100,"<>Hủy",Registrations!$L$2:$L100,"<>Từ chối") -> 0 | G14: =IFERROR(__xludf.DUMMYFUNCTION("IFERROR(INDEX(FILTER(Registrations!$D$2:$D100,Registrations!$H$2:$H100=$C14,Registrations!$L$2:$L100<>""Hủy"",Registrations!$L$2:$L100<>""Từ chối""),1),"""")"),"") | H14: =IFERROR(__xludf.DUMMYFUNCTION("IFERROR(INDEX(FILTER(Registrations!$E$2:$E100,Registrations!$H$2:$H100=$C14,Registrations!$L$2:$L100<>""Hủy"",Registrations!$L$2:$L100<>""Từ chối""),1),"""")"),"") | I14: =IFERROR(__xludf.DUMMYFUNCTION("IF(F14=0,"""",IF(IFERROR(INDEX(FILTER(Registrations!$F$2:$F100,Registrations!$H$2:$H100=$C14,Registrations!$L$2:$L100<>""Hủy"",Registrations!$L$2:$L100<>""Từ chối""),1),"""")=$A14,""Khớp"",""Sai kho""))"),"") | J14: B | K14: 17622500
A15: AYC | B15: 14 | C15: #014 | D15: OLED77C44LA.AEUQLHX | E15: =IF(F15=0,"Còn trống",IF(F15=1,"Đã đăng ký","Trùng đăng ký")) -> Còn trống | F15: =COUNTIFS(Registrations!$H$2:$H100,$C15,Registrations!$L$2:$L100,"<>Hủy",Registrations!$L$2:$L100,"<>Từ chối") -> 0 | G15: =IFERROR(__xludf.DUMMYFUNCTION("IFERROR(INDEX(FILTER(Registrations!$D$2:$D100,Registrations!$H$2:$H100=$C15,Registrations!$L$2:$L100<>""Hủy"",Registrations!$L$2:$L100<>""Từ chối""),1),"""")"),"") | H15: =IFERROR(__xludf.DUMMYFUNCTION("IFERROR(INDEX(FILTER(Registrations!$E$2:$E100,Registrations!$H$2:$H100=$C15,Registrations!$L$2:$L100<>""Hủy"",Registrations!$L$2:$L100<>""Từ chối""),1),"""")"),"") | I15: =IFERROR(__xludf.DUMMYFUNCTION("IF(F15=0,"""",IF(IFERROR(INDEX(FILTER(Registrations!$F$2:$F100,Registrations!$H$2:$H100=$C15,Registrations!$L$2:$L100<>""Hủy"",Registrations!$L$2:$L100<>""Từ chối""),1),"""")=$A15,""Khớp"",""Sai kho""))"),"") | J15: B | K15: 13975000
A16: AYC | B16: 15 | C16: #015 | D16: OLED77C54LA.AEUQLHX | E16: =IF(F16=0,"Còn trống",IF(F16=1,"Đã đăng ký","Trùng đăng ký")) -> Còn trống | F16: =COUNTIFS(Registrations!$H$2:$H100,$C16,Registrations!$L$2:$L100,"<>Hủy",Registrations!$L$2:$L100,"<>Từ chối") -> 0 | G16: =IFERROR(__xludf.DUMMYFUNCTION("IFERROR(INDEX(FILTER(Registrations!$D$2:$D100,Registrations!$H$2:$H100=$C16,Registrations!$L$2:$L100<>""Hủy"",Registrations!$L$2:$L100<>""Từ chối""),1),"""")"),"") | H16: =IFERROR(__xludf.DUMMYFUNCTION("IFERROR(INDEX(FILTER(Registrations!$E$2:$E100,Registrations!$H$2:$H100=$C16,Registrations!$L$2:$L100<>""Hủy"",Registrations!$L$2:$L100<>""Từ chối""),1),"""")"),"") | I16: =IFERROR(__xludf.DUMMYFUNCTION("IF(F16=0,"""",IF(IFERROR(INDEX(FILTER(Registrations!$F$2:$F100,Registrations!$H$2:$H100=$C16,Registrations!$L$2:$L100<>""Hủy"",Registrations!$L$2:$L100<>""Từ chối""),1),"""")=$A16,""Khớp"",""Sai kho""))"),"") | J16: B | K16: 14975000
A17: AYC | B17: 16 | C17: #016 | D17: OLED83B5PSA.AGAQLHX | E17: =IF(F17=0,"Còn trống",IF(F17=1,"Đã đăng ký","Trùng đăng ký")) -> Còn trống | F17: =COUNTIFS(Registrations!$H$2:$H100,$C17,Registrations!$L$2:$L100,"<>Hủy",Registrations!$L$2:$L100,"<>Từ chối") -> 0 | G17: =IFERROR(__xludf.DUMMYFUNCTION("IFERROR(INDEX(FILTER(Registrations!$D$2:$D100,Registrations!$H$2:$H100=$C17,Registrations!$L$2:$L100<>""Hủy"",Registrations!$L$2:$L100<>""Từ chối""),1),"""")"),"") | H17: =IFERROR(__xludf.DUMMYFUNCTION("IFERROR(INDEX(FILTER(Registrations!$E$2:$E100,Registrations!$H$2:$H100=$C17,Registrations!$L$2:$L100<>""Hủy"",Registrations!$L$2:$L100<>""Từ chối""),1),"""")"),"") | I17: =IFERROR(__xludf.DUMMYFUNCTION("IF(F17=0,"""",IF(IFERROR(INDEX(FILTER(Registrations!$F$2:$F100,Registrations!$H$2:$H100=$C17,Registrations!$L$2:$L100<>""Hủy"",Registrations!$L$2:$L100<>""Từ chối""),1),"""")=$A17,""Khớp"",""Sai kho""))"),"") | J17: B | K17: 16475000
A18: AYC | B18: 17 | C18: #017 | D18: OLED83M4PUA.AUSYLHX | E18: =IF(F18=0,"Còn trống",IF(F18=1,"Đã đăng ký","Trùng đăng ký")) -> Còn trống | F18: =COUNTIFS(Registrations!$H$2:$H100,$C18,Registrations!$L$2:$L100,"<>Hủy",Registrations!$L$2:$L100,"<>Từ chối") -> 0 | G18: =IFERROR(__xludf.DUMMYFUNCTION("IFERROR(INDEX(FILTER(Registrations!$D$2:$D100,Registrations!$H$2:$H100=$C18,Registrations!$L$2:$L100<>""Hủy"",Registrations!$L$2:$L100<>""Từ chối""),1),"""")"),"") | H18: =IFERROR(__xludf.DUMMYFUNCTION("IFERROR(INDEX(FILTER(Registrations!$E$2:$E100,Registrations!$H$2:$H100=$C18,Registrations!$L$2:$L100<>""Hủy"",Registrations!$L$2:$L100<>""Từ chối""),1),"""")"),"") | I18: =IFERROR(__xludf.DUMMYFUNCTION("IF(F18=0,"""",IF(IFERROR(INDEX(FILTER(Registrations!$F$2:$F100,Registrations!$H$2:$H100=$C18,Registrations!$L$2:$L100<>""Hủy"",Registrations!$L$2:$L100<>""Từ chối""),1),"""")=$A18,""Khớp"",""Sai kho""))"),"") | J18: B | K18: 17475000
A19: AYC | B19: 18 | C19: #018 | D19: OLED97M5PSA.AAU | E19: =IF(F19=0,"Còn trống",IF(F19=1,"Đã đăng ký","Trùng đăng ký")) -> Còn trống | F19: =COUNTIFS(Registrations!$H$2:$H100,$C19,Registrations!$L$2:$L100,"<>Hủy",Registrations!$L$2:$L100,"<>Từ chối") -> 0 | G19: =IFERROR(__xludf.DUMMYFUNCTION("IFERROR(INDEX(FILTER(Registrations!$D$2:$D100,Registrations!$H$2:$H100=$C19,Registrations!$L$2:$L100<>""Hủy"",Registrations!$L$2:$L100<>""Từ chối""),1),"""")"),"") | H19: =IFERROR(__xludf.DUMMYFUNCTION("IFERROR(INDEX(FILTER(Registrations!$E$2:$E100,Registrations!$H$2:$H100=$C19,Registrations!$L$2:$L100<>""Hủy"",Registrations!$L$2:$L100<>""Từ chối""),1),"""")"),"") | I19: =IFERROR(__xludf.DUMMYFUNCTION("IF(F19=0,"""",IF(IFERROR(INDEX(FILTER(Registrations!$F$2:$F100,Registrations!$H$2:$H100=$C19,Registrations!$L$2:$L100<>""Hủy"",Registrations!$L$2:$L100<>""Từ chối""),1),"""")=$A19,""Khớp"",""Sai kho""))"),"") | J19: B | K19: 25000000
A20: AYC | B20: 19 | C20: #019 | D20: OLED77C6PJA.AJLQLHX | E20: =IF(F20=0,"Còn trống",IF(F20=1,"Đã đăng ký","Trùng đăng ký")) -> Còn trống | F20: =COUNTIFS(Registrations!$H$2:$H100,$C20,Registrations!$L$2:$L100,"<>Hủy",Registrations!$L$2:$L100,"<>Từ chối") -> 0 | G20: =IFERROR(__xludf.DUMMYFUNCTION("IFERROR(INDEX(FILTER(Registrations!$D$2:$D100,Registrations!$H$2:$H100=$C20,Registrations!$L$2:$L100<>""Hủy"",Registrations!$L$2:$L100<>""Từ chối""),1),"""")"),"") | H20: =IFERROR(__xludf.DUMMYFUNCTION("IFERROR(INDEX(FILTER(Registrations!$E$2:$E100,Registrations!$H$2:$H100=$C20,Registrations!$L$2:$L100<>""Hủy"",Registrations!$L$2:$L100<>""Từ chối""),1),"""")"),"") | I20: =IFERROR(__xludf.DUMMYFUNCTION("IF(F20=0,"""",IF(IFERROR(INDEX(FILTER(Registrations!$F$2:$F100,Registrations!$H$2:$H100=$C20,Registrations!$L$2:$L100<>""Hủy"",Registrations!$L$2:$L100<>""Từ chối""),1),"""")=$A20,""Khớp"",""Sai kho""))"),"") | J20: GoodSet | K20: 17950000
A21: AYC | B21: 20 | C21: #020 | D21: OLED77B6PCA.ACNQLHX | E21: =IF(F21=0,"Còn trống",IF(F21=1,"Đã đăng ký","Trùng đăng ký")) -> Còn trống | F21: =COUNTIFS(Registrations!$H$2:$H100,$C21,Registrations!$L$2:$L100,"<>Hủy",Registrations!$L$2:$L100,"<>Từ chối") -> 0 | G21: =IFERROR(__xludf.DUMMYFUNCTION("IFERROR(INDEX(FILTER(Registrations!$D$2:$D100,Registrations!$H$2:$H100=$C21,Registrations!$L$2:$L100<>""Hủy"",Registrations!$L$2:$L100<>""Từ chối""),1),"""")"),"") | H21: =IFERROR(__xludf.DUMMYFUNCTION("IFERROR(INDEX(FILTER(Registrations!$E$2:$E100,Registrations!$H$2:$H100=$C21,Registrations!$L$2:$L100<>""Hủy"",Registrations!$L$2:$L100<>""Từ chối""),1),"""")"),"") | I21: =IFERROR(__xludf.DUMMYFUNCTION("IF(F21=0,"""",IF(IFERROR(INDEX(FILTER(Registrations!$F$2:$F100,Registrations!$H$2:$H100=$C21,Registrations!$L$2:$L100<>""Hủy"",Registrations!$L$2:$L100<>""Từ chối""),1),"""")=$A21,""Khớp"",""Sai kho""))"),"") | J21: GoodSet | K21: 13450000
A22: AYC | B22: 21 | C22: #021 | D22: 75QNED70BSA.AGAFLHX | E22: =IF(F22=0,"Còn trống",IF(F22=1,"Đã đăng ký","Trùng đăng ký")) -> Còn trống | F22: =COUNTIFS(Registrations!$H$2:$H100,$C22,Registrations!$L$2:$L100,"<>Hủy",Registrations!$L$2:$L100,"<>Từ chối") -> 0 | G22: =IFERROR(__xludf.DUMMYFUNCTION("IFERROR(INDEX(FILTER(Registrations!$D$2:$D100,Registrations!$H$2:$H100=$C22,Registrations!$L$2:$L100<>""Hủy"",Registrations!$L$2:$L100<>""Từ chối""),1),"""")"),"") | H22: =IFERROR(__xludf.DUMMYFUNCTION("IFERROR(INDEX(FILTER(Registrations!$E$2:$E100,Registrations!$H$2:$H100=$C22,Registrations!$L$2:$L100<>""Hủy"",Registrations!$L$2:$L100<>""Từ chối""),1),"""")"),"") | I22: =IFERROR(__xludf.DUMMYFUNCTION("IF(F22=0,"""",IF(IFERROR(INDEX(FILTER(Registrations!$F$2:$F100,Registrations!$H$2:$H100=$C22,Registrations!$L$2:$L100<>""Hủy"",Registrations!$L$2:$L100<>""Từ chối""),1),"""")=$A22,""Khớp"",""Sai kho""))"),"") | J22: GoodSet | K22: 8450000
A23: AYC | B23: 22 | C23: #022 | D23: 75QNED81B6A.AEUNLHX | E23: =IF(F23=0,"Còn trống",IF(F23=1,"Đã đăng ký","Trùng đăng ký")) -> Còn trống | F23: =COUNTIFS(Registrations!$H$2:$H100,$C23,Registrations!$L$2:$L100,"<>Hủy",Registrations!$L$2:$L100,"<>Từ chối") -> 0 | G23: =IFERROR(__xludf.DUMMYFUNCTION("IFERROR(INDEX(FILTER(Registrations!$D$2:$D100,Registrations!$H$2:$H100=$C23,Registrations!$L$2:$L100<>""Hủy"",Registrations!$L$2:$L100<>""Từ chối""),1),"""")"),"") | H23: =IFERROR(__xludf.DUMMYFUNCTION("IFERROR(INDEX(FILTER(Registrations!$E$2:$E100,Registrations!$H$2:$H100=$C23,Registrations!$L$2:$L100<>""Hủy"",Registrations!$L$2:$L100<>""Từ chối""),1),"""")"),"") | I23: =IFERROR(__xludf.DUMMYFUNCTION("IF(F23=0,"""",IF(IFERROR(INDEX(FILTER(Registrations!$F$2:$F100,Registrations!$H$2:$H100=$C23,Registrations!$L$2:$L100<>""Hủy"",Registrations!$L$2:$L100<>""Từ chối""),1),"""")=$A23,""Khớp"",""Sai kho""))"),"") | J23: GoodSet | K23: 9450000
A24: AYC | B24: 23 | C24: #023 | D24: 65NU850BPUA.AUSFLHX | E24: =IF(F24=0,"Còn trống",IF(F24=1,"Đã đăng ký","Trùng đăng ký")) -> Còn trống | F24: =COUNTIFS(Registrations!$H$2:$H100,$C24,Registrations!$L$2:$L100,"<>Hủy",Registrations!$L$2:$L100,"<>Từ chối") -> 0 | G24: =IFERROR(__xludf.DUMMYFUNCTION("IFERROR(INDEX(FILTER(Registrations!$D$2:$D100,Registrations!$H$2:$H100=$C24,Registrations!$L$2:$L100<>""Hủy"",Registrations!$L$2:$L100<>""Từ chối""),1),"""")"),"") | H24: =IFERROR(__xludf.DUMMYFUNCTION("IFERROR(INDEX(FILTER(Registrations!$E$2:$E100,Registrations!$H$2:$H100=$C24,Registrations!$L$2:$L100<>""Hủy"",Registrations!$L$2:$L100<>""Từ chối""),1),"""")"),"") | I24: =IFERROR(__xludf.DUMMYFUNCTION("IF(F24=0,"""",IF(IFERROR(INDEX(FILTER(Registrations!$F$2:$F100,Registrations!$H$2:$H100=$C24,Registrations!$L$2:$L100<>""Hủy"",Registrations!$L$2:$L100<>""Từ chối""),1),"""")=$A24,""Khớp"",""Sai kho""))"),"") | J24: GoodSet | K24: 6950000
A25: AYC | B25: 24 | C25: #024 | D25: 75MRGB86BSA.AGADLHX | E25: =IF(F25=0,"Còn trống",IF(F25=1,"Đã đăng ký","Trùng đăng ký")) -> Còn trống | F25: =COUNTIFS(Registrations!$H$2:$H100,$C25,Registrations!$L$2:$L100,"<>Hủy",Registrations!$L$2:$L100,"<>Từ chối") -> 0 | G25: =IFERROR(__xludf.DUMMYFUNCTION("IFERROR(INDEX(FILTER(Registrations!$D$2:$D100,Registrations!$H$2:$H100=$C25,Registrations!$L$2:$L100<>""Hủy"",Registrations!$L$2:$L100<>""Từ chối""),1),"""")"),"") | H25: =IFERROR(__xludf.DUMMYFUNCTION("IFERROR(INDEX(FILTER(Registrations!$E$2:$E100,Registrations!$H$2:$H100=$C25,Registrations!$L$2:$L100<>""Hủy"",Registrations!$L$2:$L100<>""Từ chối""),1),"""")"),"") | I25: =IFERROR(__xludf.DUMMYFUNCTION("IF(F25=0,"""",IF(IFERROR(INDEX(FILTER(Registrations!$F$2:$F100,Registrations!$H$2:$H100=$C25,Registrations!$L$2:$L100<>""Hủy"",Registrations!$L$2:$L100<>""Từ chối""),1),"""")=$A25,""Khớp"",""Sai kho""))"),"") | J25: GoodSet | K25: 17450000
A26: AYA | B26: 25 | C26: #025 | D26: 100QNED89AS.AGAFLHX | E26: =IF(F26=0,"Còn trống",IF(F26=1,"Đã đăng ký","Trùng đăng ký")) -> Còn trống | F26: =COUNTIFS(Registrations!$H$2:$H100,$C26,Registrations!$L$2:$L100,"<>Hủy",Registrations!$L$2:$L100,"<>Từ chối") -> 0 | G26: =IFERROR(__xludf.DUMMYFUNCTION("IFERROR(INDEX(FILTER(Registrations!$D$2:$D100,Registrations!$H$2:$H100=$C26,Registrations!$L$2:$L100<>""Hủy"",Registrations!$L$2:$L100<>""Từ chối""),1),"""")"),"") | H26: =IFERROR(__xludf.DUMMYFUNCTION("IFERROR(INDEX(FILTER(Registrations!$E$2:$E100,Registrations!$H$2:$H100=$C26,Registrations!$L$2:$L100<>""Hủy"",Registrations!$L$2:$L100<>""Từ chối""),1),"""")"),"") | I26: =IFERROR(__xludf.DUMMYFUNCTION("IF(F26=0,"""",IF(IFERROR(INDEX(FILTER(Registrations!$F$2:$F100,Registrations!$H$2:$H100=$C26,Registrations!$L$2:$L100<>""Hủy"",Registrations!$L$2:$L100<>""Từ chối""),1),"""")=$A26,""Khớp"",""Sai kho""))"),"") | J26: B | K26: 22475000
A27: AYA | B27: 26 | C27: #026 | D27: 27LX6TDGA.ATV | E27: =IF(F27=0,"Còn trống",IF(F27=1,"Đã đăng ký","Trùng đăng ký")) -> Còn trống | F27: =COUNTIFS(Registrations!$H$2:$H100,$C27,Registrations!$L$2:$L100,"<>Hủy",Registrations!$L$2:$L100,"<>Từ chối") -> 0 | G27: =IFERROR(__xludf.DUMMYFUNCTION("IFERROR(INDEX(FILTER(Registrations!$D$2:$D100,Registrations!$H$2:$H100=$C27,Registrations!$L$2:$L100<>""Hủy"",Registrations!$L$2:$L100<>""Từ chối""),1),"""")"),"") | H27: =IFERROR(__xludf.DUMMYFUNCTION("IFERROR(INDEX(FILTER(Registrations!$E$2:$E100,Registrations!$H$2:$H100=$C27,Registrations!$L$2:$L100<>""Hủy"",Registrations!$L$2:$L100<>""Từ chối""),1),"""")"),"") | I27: =IFERROR(__xludf.DUMMYFUNCTION("IF(F27=0,"""",IF(IFERROR(INDEX(FILTER(Registrations!$F$2:$F100,Registrations!$H$2:$H100=$C27,Registrations!$L$2:$L100<>""Hủy"",Registrations!$L$2:$L100<>""Từ chối""),1),"""")=$A27,""Khớp"",""Sai kho""))"),"") | J27: B | K27: 5085000
A28: AYA | B28: 27 | C28: #027 | D28: 27LX6TDGA.ATV | E28: =IF(F28=0,"Còn trống",IF(F28=1,"Đã đăng ký","Trùng đăng ký")) -> Còn trống | F28: =COUNTIFS(Registrations!$H$2:$H100,$C28,Registrations!$L$2:$L100,"<>Hủy",Registrations!$L$2:$L100,"<>Từ chối") -> 0 | G28: =IFERROR(__xludf.DUMMYFUNCTION("IFERROR(INDEX(FILTER(Registrations!$D$2:$D100,Registrations!$H$2:$H100=$C28,Registrations!$L$2:$L100<>""Hủy"",Registrations!$L$2:$L100<>""Từ chối""),1),"""")"),"") | H28: =IFERROR(__xludf.DUMMYFUNCTION("IFERROR(INDEX(FILTER(Registrations!$E$2:$E100,Registrations!$H$2:$H100=$C28,Registrations!$L$2:$L100<>""Hủy"",Registrations!$L$2:$L100<>""Từ chối""),1),"""")"),"") | I28: =IFERROR(__xludf.DUMMYFUNCTION("IF(F28=0,"""",IF(IFERROR(INDEX(FILTER(Registrations!$F$2:$F100,Registrations!$H$2:$H100=$C28,Registrations!$L$2:$L100<>""Hủy"",Registrations!$L$2:$L100<>""Từ chối""),1),"""")=$A28,""Khớp"",""Sai kho""))"),"") | J28: B | K28: 5085000
A29: AYA | B29: 28 | C29: #028 | D29: 27LX6TDGA.ATV | E29: =IF(F29=0,"Còn trống",IF(F29=1,"Đã đăng ký","Trùng đăng ký")) -> Còn trống | F29: =COUNTIFS(Registrations!$H$2:$H100,$C29,Registrations!$L$2:$L100,"<>Hủy",Registrations!$L$2:$L100,"<>Từ chối") -> 0 | G29: =IFERROR(__xludf.DUMMYFUNCTION("IFERROR(INDEX(FILTER(Registrations!$D$2:$D100,Registrations!$H$2:$H100=$C29,Registrations!$L$2:$L100<>""Hủy"",Registrations!$L$2:$L100<>""Từ chối""),1),"""")"),"") | H29: =IFERROR(__xludf.DUMMYFUNCTION("IFERROR(INDEX(FILTER(Registrations!$E$2:$E100,Registrations!$H$2:$H100=$C29,Registrations!$L$2:$L100<>""Hủy"",Registrations!$L$2:$L100<>""Từ chối""),1),"""")"),"") | I29: =IFERROR(__xludf.DUMMYFUNCTION("IF(F29=0,"""",IF(IFERROR(INDEX(FILTER(Registrations!$F$2:$F100,Registrations!$H$2:$H100=$C29,Registrations!$L$2:$L100<>""Hủy"",Registrations!$L$2:$L100<>""Từ chối""),1),"""")=$A29,""Khớp"",""Sai kho""))"),"") | J29: B | K29: 5085000
A30: AYA | B30: 29 | C30: #029 | D30: 43LB6500PSB.AWZSLHX | E30: =IF(F30=0,"Còn trống",IF(F30=1,"Đã đăng ký","Trùng đăng ký")) -> Còn trống | F30: =COUNTIFS(Registrations!$H$2:$H100,$C30,Registrations!$L$2:$L100,"<>Hủy",Registrations!$L$2:$L100,"<>Từ chối") -> 0 | G30: =IFERROR(__xludf.DUMMYFUNCTION("IFERROR(INDEX(FILTER(Registrations!$D$2:$D100,Registrations!$H$2:$H100=$C30,Registrations!$L$2:$L100<>""Hủy"",Registrations!$L$2:$L100<>""Từ chối""),1),"""")"),"") | H30: =IFERROR(__xludf.DUMMYFUNCTION("IFERROR(INDEX(FILTER(Registrations!$E$2:$E100,Registrations!$H$2:$H100=$C30,Registrations!$L$2:$L100<>""Hủy"",Registrations!$L$2:$L100<>""Từ chối""),1),"""")"),"") | I30: =IFERROR(__xludf.DUMMYFUNCTION("IF(F30=0,"""",IF(IFERROR(INDEX(FILTER(Registrations!$F$2:$F100,Registrations!$H$2:$H100=$C30,Registrations!$L$2:$L100<>""Hủy"",Registrations!$L$2:$L100<>""Từ chối""),1),"""")=$A30,""Khớp"",""Sai kho""))"),"") | J30: B | K30: 903500
A31: AYA | B31: 30 | C31: #030 | D31: 65UA8055PSA.ATV | E31: =IF(F31=0,"Còn trống",IF(F31=1,"Đã đăng ký","Trùng đăng ký")) -> Còn trống | F31: =COUNTIFS(Registrations!$H$2:$H100,$C31,Registrations!$L$2:$L100,"<>Hủy",Registrations!$L$2:$L100,"<>Từ chối") -> 0 | G31: =IFERROR(__xludf.DUMMYFUNCTION("IFERROR(INDEX(FILTER(Registrations!$D$2:$D100,Registrations!$H$2:$H100=$C31,Registrations!$L$2:$L100<>""Hủy"",Registrations!$L$2:$L100<>""Từ chối""),1),"""")"),"") | H31: =IFERROR(__xludf.DUMMYFUNCTION("IFERROR(INDEX(FILTER(Registrations!$E$2:$E100,Registrations!$H$2:$H100=$C31,Registrations!$L$2:$L100<>""Hủy"",Registrations!$L$2:$L100<>""Từ chối""),1),"""")"),"") | I31: =IFERROR(__xludf.DUMMYFUNCTION("IF(F31=0,"""",IF(IFERROR(INDEX(FILTER(Registrations!$F$2:$F100,Registrations!$H$2:$H100=$C31,Registrations!$L$2:$L100<>""Hủy"",Registrations!$L$2:$L100<>""Từ chối""),1),"""")=$A31,""Khớp"",""Sai kho""))"),"") | J31: A | K31: 4872500
A32: AYA | B32: 31 | C32: #031 | D32: 75QNED86ASA.ATV | E32: =IF(F32=0,"Còn trống",IF(F32=1,"Đã đăng ký","Trùng đăng ký")) -> Còn trống | F32: =COUNTIFS(Registrations!$H$2:$H100,$C32,Registrations!$L$2:$L100,"<>Hủy",Registrations!$L$2:$L100,"<>Từ chối") -> 0 | G32: =IFERROR(__xludf.DUMMYFUNCTION("IFERROR(INDEX(FILTER(Registrations!$D$2:$D100,Registrations!$H$2:$H100=$C32,Registrations!$L$2:$L100<>""Hủy"",Registrations!$L$2:$L100<>""Từ chối""),1),"""")"),"") | H32: =IFERROR(__xludf.DUMMYFUNCTION("IFERROR(INDEX(FILTER(Registrations!$E$2:$E100,Registrations!$H$2:$H100=$C32,Registrations!$L$2:$L100<>""Hủy"",Registrations!$L$2:$L100<>""Từ chối""),1),"""")"),"") | I32: =IFERROR(__xludf.DUMMYFUNCTION("IF(F32=0,"""",IF(IFERROR(INDEX(FILTER(Registrations!$F$2:$F100,Registrations!$H$2:$H100=$C32,Registrations!$L$2:$L100<>""Hủy"",Registrations!$L$2:$L100<>""Từ chối""),1),"""")=$A32,""Khớp"",""Sai kho""))"),"") | J32: B | K32: 10022500
A33: AYA | B33: 32 | C33: #032 | D33: 75QNED9MASA.AGAFLHX | E33: =IF(F33=0,"Còn trống",IF(F33=1,"Đã đăng ký","Trùng đăng ký")) -> Còn trống | F33: =COUNTIFS(Registrations!$H$2:$H100,$C33,Registrations!$L$2:$L100,"<>Hủy",Registrations!$L$2:$L100,"<>Từ chối") -> 0 | G33: =IFERROR(__xludf.DUMMYFUNCTION("IFERROR(INDEX(FILTER(Registrations!$D$2:$D100,Registrations!$H$2:$H100=$C33,Registrations!$L$2:$L100<>""Hủy"",Registrations!$L$2:$L100<>""Từ chối""),1),"""")"),"") | H33: =IFERROR(__xludf.DUMMYFUNCTION("IFERROR(INDEX(FILTER(Registrations!$E$2:$E100,Registrations!$H$2:$H100=$C33,Registrations!$L$2:$L100<>""Hủy"",Registrations!$L$2:$L100<>""Từ chối""),1),"""")"),"") | I33: =IFERROR(__xludf.DUMMYFUNCTION("IF(F33=0,"""",IF(IFERROR(INDEX(FILTER(Registrations!$F$2:$F100,Registrations!$H$2:$H100=$C33,Registrations!$L$2:$L100<>""Hủy"",Registrations!$L$2:$L100<>""Từ chối""),1),"""")=$A33,""Khớp"",""Sai kho""))"),"") | J33: B | K33: 12475000
A34: AYA | B34: 33 | C34: #033 | D34: OLED48B5PSA.ATV | E34: =IF(F34=0,"Còn trống",IF(F34=1,"Đã đăng ký","Trùng đăng ký")) -> Còn trống | F34: =COUNTIFS(Registrations!$H$2:$H100,$C34,Registrations!$L$2:$L100,"<>Hủy",Registrations!$L$2:$L100,"<>Từ chối") -> 0 | G34: =IFERROR(__xludf.DUMMYFUNCTION("IFERROR(INDEX(FILTER(Registrations!$D$2:$D100,Registrations!$H$2:$H100=$C34,Registrations!$L$2:$L100<>""Hủy"",Registrations!$L$2:$L100<>""Từ chối""),1),"""")"),"") | H34: =IFERROR(__xludf.DUMMYFUNCTION("IFERROR(INDEX(FILTER(Registrations!$E$2:$E100,Registrations!$H$2:$H100=$C34,Registrations!$L$2:$L100<>""Hủy"",Registrations!$L$2:$L100<>""Từ chối""),1),"""")"),"") | I34: =IFERROR(__xludf.DUMMYFUNCTION("IF(F34=0,"""",IF(IFERROR(INDEX(FILTER(Registrations!$F$2:$F100,Registrations!$H$2:$H100=$C34,Registrations!$L$2:$L100<>""Hủy"",Registrations!$L$2:$L100<>""Từ chối""),1),"""")=$A34,""Khớp"",""Sai kho""))"),"") | J34: B | K34: 7322500
A35: AYA | B35: 34 | C35: #034 | D35: OLED65G5PSA.ATV | E35: =IF(F35=0,"Còn trống",IF(F35=1,"Đã đăng ký","Trùng đăng ký")) -> Còn trống | F35: =COUNTIFS(Registrations!$H$2:$H100,$C35,Registrations!$L$2:$L100,"<>Hủy",Registrations!$L$2:$L100,"<>Từ chối") -> 0 | G35: =IFERROR(__xludf.DUMMYFUNCTION("IFERROR(INDEX(FILTER(Registrations!$D$2:$D100,Registrations!$H$2:$H100=$C35,Registrations!$L$2:$L100<>""Hủy"",Registrations!$L$2:$L100<>""Từ chối""),1),"""")"),"") | H35: =IFERROR(__xludf.DUMMYFUNCTION("IFERROR(INDEX(FILTER(Registrations!$E$2:$E100,Registrations!$H$2:$H100=$C35,Registrations!$L$2:$L100<>""Hủy"",Registrations!$L$2:$L100<>""Từ chối""),1),"""")"),"") | I35: =IFERROR(__xludf.DUMMYFUNCTION("IF(F35=0,"""",IF(IFERROR(INDEX(FILTER(Registrations!$F$2:$F100,Registrations!$H$2:$H100=$C35,Registrations!$L$2:$L100<>""Hủy"",Registrations!$L$2:$L100<>""Từ chối""),1),"""")=$A35,""Khớp"",""Sai kho""))"),"") | J35: B | K35: 17622500
A36: AYA | B36: 35 | C36: #035 | D36: OLED77C44LA.AEUQLHX | E36: =IF(F36=0,"Còn trống",IF(F36=1,"Đã đăng ký","Trùng đăng ký")) -> Còn trống | F36: =COUNTIFS(Registrations!$H$2:$H100,$C36,Registrations!$L$2:$L100,"<>Hủy",Registrations!$L$2:$L100,"<>Từ chối") -> 0 | G36: =IFERROR(__xludf.DUMMYFUNCTION("IFERROR(INDEX(FILTER(Registrations!$D$2:$D100,Registrations!$H$2:$H100=$C36,Registrations!$L$2:$L100<>""Hủy"",Registrations!$L$2:$L100<>""Từ chối""),1),"""")"),"") | H36: =IFERROR(__xludf.DUMMYFUNCTION("IFERROR(INDEX(FILTER(Registrations!$E$2:$E100,Registrations!$H$2:$H100=$C36,Registrations!$L$2:$L100<>""Hủy"",Registrations!$L$2:$L100<>""Từ chối""),1),"""")"),"") | I36: =IFERROR(__xludf.DUMMYFUNCTION("IF(F36=0,"""",IF(IFERROR(INDEX(FILTER(Registrations!$F$2:$F100,Registrations!$H$2:$H100=$C36,Registrations!$L$2:$L100<>""Hủy"",Registrations!$L$2:$L100<>""Từ chối""),1),"""")=$A36,""Khớp"",""Sai kho""))"),"") | J36: B | K36: 13975000
A37: AYA | B37: 36 | C37: #036 | D37: OLED77C54LA.AEUQLHX | E37: =IF(F37=0,"Còn trống",IF(F37=1,"Đã đăng ký","Trùng đăng ký")) -> Còn trống | F37: =COUNTIFS(Registrations!$H$2:$H100,$C37,Registrations!$L$2:$L100,"<>Hủy",Registrations!$L$2:$L100,"<>Từ chối") -> 0 | G37: =IFERROR(__xludf.DUMMYFUNCTION("IFERROR(INDEX(FILTER(Registrations!$D$2:$D100,Registrations!$H$2:$H100=$C37,Registrations!$L$2:$L100<>""Hủy"",Registrations!$L$2:$L100<>""Từ chối""),1),"""")"),"") | H37: =IFERROR(__xludf.DUMMYFUNCTION("IFERROR(INDEX(FILTER(Registrations!$E$2:$E100,Registrations!$H$2:$H100=$C37,Registrations!$L$2:$L100<>""Hủy"",Registrations!$L$2:$L100<>""Từ chối""),1),"""")"),"") | I37: =IFERROR(__xludf.DUMMYFUNCTION("IF(F37=0,"""",IF(IFERROR(INDEX(FILTER(Registrations!$F$2:$F100,Registrations!$H$2:$H100=$C37,Registrations!$L$2:$L100<>""Hủy"",Registrations!$L$2:$L100<>""Từ chối""),1),"""")=$A37,""Khớp"",""Sai kho""))"),"") | J37: B | K37: 14975000
A38: AYA | B38: 37 | C38: #037 | D38: OLED83B5PSA.AGAQLHX | E38: =IF(F38=0,"Còn trống",IF(F38=1,"Đã đăng ký","Trùng đăng ký")) -> Còn trống | F38: =COUNTIFS(Registrations!$H$2:$H100,$C38,Registrations!$L$2:$L100,"<>Hủy",Registrations!$L$2:$L100,"<>Từ chối") -> 0 | G38: =IFERROR(__xludf.DUMMYFUNCTION("IFERROR(INDEX(FILTER(Registrations!$D$2:$D100,Registrations!$H$2:$H100=$C38,Registrations!$L$2:$L100<>""Hủy"",Registrations!$L$2:$L100<>""Từ chối""),1),"""")"),"") | H38: =IFERROR(__xludf.DUMMYFUNCTION("IFERROR(INDEX(FILTER(Registrations!$E$2:$E100,Registrations!$H$2:$H100=$C38,Registrations!$L$2:$L100<>""Hủy"",Registrations!$L$2:$L100<>""Từ chối""),1),"""")"),"") | I38: =IFERROR(__xludf.DUMMYFUNCTION("IF(F38=0,"""",IF(IFERROR(INDEX(FILTER(Registrations!$F$2:$F100,Registrations!$H$2:$H100=$C38,Registrations!$L$2:$L100<>""Hủy"",Registrations!$L$2:$L100<>""Từ chối""),1),"""")=$A38,""Khớp"",""Sai kho""))"),"") | J38: B | K38: 16475000
A39: AYA | B39: 38 | C39: #038 | D39: OLED83C5PSA.AWZQLHX | E39: =IF(F39=0,"Còn trống",IF(F39=1,"Đã đăng ký","Trùng đăng ký")) -> Còn trống | F39: =COUNTIFS(Registrations!$H$2:$H100,$C39,Registrations!$L$2:$L100,"<>Hủy",Registrations!$L$2:$L100,"<>Từ chối") -> 0 | G39: =IFERROR(__xludf.DUMMYFUNCTION("IFERROR(INDEX(FILTER(Registrations!$D$2:$D100,Registrations!$H$2:$H100=$C39,Registrations!$L$2:$L100<>""Hủy"",Registrations!$L$2:$L100<>""Từ chối""),1),"""")"),"") | H39: =IFERROR(__xludf.DUMMYFUNCTION("IFERROR(INDEX(FILTER(Registrations!$E$2:$E100,Registrations!$H$2:$H100=$C39,Registrations!$L$2:$L100<>""Hủy"",Registrations!$L$2:$L100<>""Từ chối""),1),"""")"),"") | I39: =IFERROR(__xludf.DUMMYFUNCTION("IF(F39=0,"""",IF(IFERROR(INDEX(FILTER(Registrations!$F$2:$F100,Registrations!$H$2:$H100=$C39,Registrations!$L$2:$L100<>""Hủy"",Registrations!$L$2:$L100<>""Từ chối""),1),"""")=$A39,""Khớp"",""Sai kho""))"),"") | J39: B | K39: 17475000
A40: AYA | B40: 39 | C40: #039 | D40: OLED77C6PJA.AJLQLHX | E40: =IF(F40=0,"Còn trống",IF(F40=1,"Đã đăng ký","Trùng đăng ký")) -> Còn trống | F40: =COUNTIFS(Registrations!$H$2:$H100,$C40,Registrations!$L$2:$L100,"<>Hủy",Registrations!$L$2:$L100,"<>Từ chối") -> 0 | G40: =IFERROR(__xludf.DUMMYFUNCTION("IFERROR(INDEX(FILTER(Registrations!$D$2:$D100,Registrations!$H$2:$H100=$C40,Registrations!$L$2:$L100<>""Hủy"",Registrations!$L$2:$L100<>""Từ chối""),1),"""")"),"") | H40: =IFERROR(__xludf.DUMMYFUNCTION("IFERROR(INDEX(FILTER(Registrations!$E$2:$E100,Registrations!$H$2:$H100=$C40,Registrations!$L$2:$L100<>""Hủy"",Registrations!$L$2:$L100<>""Từ chối""),1),"""")"),"") | I40: =IFERROR(__xludf.DUMMYFUNCTION("IF(F40=0,"""",IF(IFERROR(INDEX(FILTER(Registrations!$F$2:$F100,Registrations!$H$2:$H100=$C40,Registrations!$L$2:$L100<>""Hủy"",Registrations!$L$2:$L100<>""Từ chối""),1),"""")=$A40,""Khớp"",""Sai kho""))"),"") | J40: GoodSet | K40: 17950000
...

Sheet Divisions
A1: Bộ Phận | B1: Nhóm
A2: CUSTOMER CARE & SERVICE DIRECTOR | B2: Quản lý & khác
A3: D2C DEPARTMENT HEAD | B3: Quản lý & khác
A4: ES CAC PM | B4: Quản lý & khác
A5: GTM DEPARTMENT | B5: Quản lý & khác
A6: HCM BRANCH | B6: HCM
A7: HCM BUSINESS PLANNING | B7: HCM
A8: HCM DEMAND PLANNING | B8: HCM
A9: HCM DX Marketing | B9: HCM
A10: HCM MARKETING SUPPORT (B2B) | B10: HCM
A11: HCM MOBILE FIELD TEST | B11: HCM
A12: HCM NEW BIZ DEVELOPMENT | B12: HCM
... A174: OTHER | B174: OTHER

Sheet Config
A1: Key | B1: Value | C1: Description
A2: CAMPAIGN_CODE | C2: Mã đợt bán, ví dụ IS-2026-10-01
A3: CAMPAIGN_NAME | C3: Tên đợt bán hiển thị trên trang đăng ký
A4: OPEN_TIME | C4: Thời điểm mở cổng (dd/mm/yyyy hh:mm)
A5: CLOSE_TIME | C5: Hạn chót đăng ký (dd/mm/yyyy hh:mm)
A6: MAX_PER_EMPLOYEE | B6: 1 | C6: Hạn mức sản phẩm cho mỗi nhân viên (theo portal)
A7: WAREHOUSES | B7: AYA, AYB, AYC | C7: Danh sách kho
A8: SLOT_TOTAL | B8: =COUNTA(Slots!$C$2:$C$91) -> 90 | C8: Tự đếm từ sheet Slots
A9: PIC_EMAIL_PRIMARY | C9: Email PM phụ trách, nhận thông báo đăng ký
A10: PIC_EMAIL_CC | C10: Email CC (để trống nếu không có)
A11: PIC_NAME_PRIMARY | C11: Tên hiển thị PM phụ trách
A12: BANK_ACCOUNT_NAME | B12: CÔNG TY TNHH LG ELECTRONICS VIỆT NAM HẢI PHÒNG | C12: Lấy từ bản mẫu portal. Cần Tài chính xác nhận trước khi dùng
A13: BANK_ACCOUNT_NO | B13: 0991000012525 | C13: Lấy từ bản mẫu portal. Cần Tài chính xác nhận trước khi dùng
A14: BANK_NAME | B14: Vietcombank - Chi nhánh Tây Hồ | C14: Lấy từ bản mẫu portal. Cần Tài chính xác nhận trước khi dùng
A15: TRANSFER_SYNTAX | B15: [Mã NV] - [Họ Tên] - [Mã Model] - [Slot ID] | C15: Cú pháp nội dung chuyển khoản
A17: Ô nền vàng: cần điền hoặc cần xác nhận trước khi mở đợt bán.

Sheet ActivityLog
A1: Timestamp | B1: Action | C1: Mã NV | D1: Slot ID | E1: User Agent | F1: Details
A2: 46293.742 | B2: REGISTER | C2: TEST001 | D2: #090 | E2: TEST-Claude | F2: Dòng 2
A3: 46293.742 | B3: REGISTER_REJECTED_DUP_SLOT | C3: TEST002 | D3: #090 | E3: TEST-Claude | F3: Slot đã có người đăng ký, không ghi đơn
A4: 46293.742 | B4: PAYMENT | C4: TEST001 | D4: #090 | E4: TEST-Claude | F4: Dòng 2 | chưa có file biên lai
A5: 46293.88 | B5: REGISTER | C5: TESTC05 | D5: #089 | E5: TEST-dongthoi | F5: Dòng 3
A6: 46293.88 | B6: REGISTER_REJECTED_DUP_SLOT | C6: TESTC03 | D6: #089 | E6: TEST-dongthoi | F6: Slot đã có người đăng ký, không ghi đơn
A7: 46293.88 | B7: REGISTER_REJECTED_DUP_SLOT | C7: TESTC02 | D7: #089 | E7: TEST-dongthoi | F7: Slot đã có người đăng ký, không ghi đơn
A8: 46293.88 | B8: REGISTER_REJECTED_DUP_SLOT | C8: TESTC04 | D8: #089 | E8: TEST-dongthoi | F8: Slot đã có người đăng ký, không ghi đơn
A9: 46293.88 | B9: REGISTER_REJECTED_DUP_SLOT | C9: TESTC01 | D9: #089 | E9: TEST-dongthoi | F9: Slot đã có người đăng ký, không ghi đơn
A10: 46293.888 | B10: REGISTER_REJECTED_DUP_SLOT | C10: TESTL1 | D10: #088 | E10: TEST-v73 | F10: Slot đã có người đăng ký, không ghi đơn
A11: 46293.888 | B11: REGISTER_REJECTED_DUP_SLOT | C11: TESTL4 | D11: #088 | E11: TEST-v73 | F11: Slot đã có người đăng ký, không ghi đơn
A12: 46293.888 | B12: REGISTER | C12: TESTL9 | D12: #088 | E12: TEST-v73 | F12: Dòng 4
A13: 46293.888 | B13: REGISTER_REJECTED_DUP_SLOT | C13: TESTL5 | D13: #088 | E13: TEST-v73 | F13: Slot đã có người đăng ký, không ghi đơn
... A19: 46293.888 | B19: REGISTER_REJECTED_DUP_SLOT | C19: TESTL2 | D19: #088 | E19: TEST-v73 | F19: Slot đã có người đăng ký, không ghi đơn
A20: 46293.888 | B20: LOOKUP_NOT_FOUND | C20: TESTL9 | E20: TEST-v73 | F20: Tra cứu không khớp
A21: 46293.889 | B21: REGISTER_REPEAT | C21: TESTL9 | D21: #088 | E21: TEST-v731 | F21: Gửi lại, đơn đã có ở dòng 4, không ghi thêm
A22: 46293.89 | B22: REGISTER | C22: TESTM19 | D22: #087 | E22: TEST-v731 | F22: Dòng 5
A23: 46293.89 | B23: REGISTER_REJECTED_DUP_SLOT | C23: TESTM17 | D23: #087 | E23: TEST-v731 | F23: Slot đã có người đăng ký, không ghi đơn
A24: 46293.89 | B24: REGISTER_REJECTED_DUP_SLOT | C24: TESTM12 | D24: #087 | E24: TEST-v731 | F24: Slot đã có người đăng ký, không ghi đơn
A25: 46293.89 | B25: REGISTER_REJECTED_DUP_SLOT | C25: TESTM14 | D25: #087 | E25: TEST-v731 | F25: Slot đã có người đăng ký, không ghi đơn
A26: 46293.89 | B26: REGISTER_REJECTED_DUP_SLOT | C26: TESTM9 | D26: #087 | E26: TEST-v731 | F26: Slot đã có người đăng ký, không ghi đơn
A27: 46293.89 | B27: REGISTER_REJECTED_DUP_SLOT | C27: TESTM10 | D27: #087 | E27: TEST-v731 | F27: Slot đã có người đăng ký, không ghi đơn
A28: 46293.89 | B28: REGISTER_REJECTED_DUP_SLOT | C28: TESTM8 | D28: #087 | E28: TEST-v731 | F28: Slot đã có người đăng ký, không ghi đơn
A29: 46293.89 | B29: REGISTER_REJECTED_DUP_SLOT | C29: TESTM3 | D29: #087 | E29: TEST-v731 | F29: Slot đã có người đăng ký, không ghi đơn
A30: 46293.89 | B30: REGISTER_REJECTED_DUP_SLOT | C30: TESTM5 | D30: #087 | E30: TEST-v731 | F30: Slot đã có người đăng ký, không ghi đơn
A31: 46293.89 | B31: REGISTER_REJECTED_DUP_SLOT | C31: TESTM15 | D31: #087 | E31: TEST-v731 | F31: Slot đã có người đăng ký, không ghi đơn
A32: 46293.89 | B32: REGISTER_REJECTED_DUP_SLOT | C32: TESTM16 | D32: #087 | E32: TEST-v731 | F32: Slot đã có người đăng ký, không ghi đơn
... A40: 46294.634 | B40: REGISTER | C40: TESTT1 | D40: #090 | E40: TEST-v74 | F40: Dòng 6

Sheet AutoEmail
A1: Họ Tên | B1: Mã NV | C1: Email | D1: Loại Email | E1: Thời Gian Gửi
